Failure in python_out_vs_err.py:
  Output line stdout:2: now stdout is broken
  failed to match line 17: things should be cool
Additional stderr output: something failed
When running command:
  /usr/bin/python python_out_vs_err.py
